<?xml version="1.0" ?>
<robot name="crab">
  <!-- Link/Joint Definitions -->
  
  <link name="base_link"/>
  
  <joint name="base_joint" type="fixed">
    <parent link="base_link"/>
    <child link="thorax"/>
    <origin rpy="0 0 0" xyz="0 0 0"/>
  </joint>

  <link name="thorax">
    <inertial>
      <origin rpy="0 0 0" xyz="0 0 0"/>
      <mass value="1.5"/>
      <inertia ixx="0.01" ixy="0" ixz="0" iyy="0.01" iyz="0" izz="0.02"/>
    </inertial>
    <visual>
      <origin rpy="0 0 0" xyz="0 0 0"/>
      <geometry>
        <mesh filename="meshes/thorax.STL"/>
      </geometry>
      <material name="grey">
        <color rgba="0.5 0.5 0.5 1"/>
      </material>
    </visual>
    <collision>
      <origin rpy="0 0 0" xyz="0 0 0"/>
      <geometry>
        <!-- Approximating thorax as a cylinder -->
        <cylinder length="0.08" radius="0.1"/>
      </geometry>
    </collision>
  </link>

  <!-- ======================================================================== -->
  <!-- Leg R1 -->
  <joint name="leg_center_joint_r1" type="fixed">
    <origin rpy="0 0 0" xyz="0.087598 -0.050575 0"/>
    <parent link="thorax"/>
    <child link="leg_center_r1"/>
  </joint>
  <link name="leg_center_r1"/>

  <joint name="coxa_joint_r1" type="revolute">
    <origin rpy="0 0 -1.0471975512" xyz="0 0 0"/>
    <parent link="leg_center_r1"/>
    <child link="coxa_r1"/>
    <axis xyz="0 0 -1"/>
    <limit effort="10" lower="-1.5" upper="1.5" velocity="5.0"/>
  </joint>
  <link name="coxa_r1">
    <inertial>
      <origin rpy="0 0 0" xyz="0.02 0 0"/>
      <mass value="0.25"/>
      <inertia ixx="0.0001" ixy="0" ixz="0" iyy="0.0001" iyz="0" izz="0.0001"/>
    </inertial>
    <visual>
      <origin rpy="0 0 0" xyz="0 0 0"/>
      <geometry>
        <mesh filename="meshes/coxa_r.STL"/>
      </geometry>
      <material name="yellow">
        <color rgba="0.7 0.7 0 1"/>
      </material>
    </visual>
    <collision>
       <origin rpy="0 1.5708 0" xyz="0.025 0 0"/>
       <geometry>
         <cylinder length="0.05" radius="0.02"/>
       </geometry>
    </collision>
  </link>

  <joint name="femur_joint_r1" type="revolute">
    <origin rpy="-1.57079632679 0 0" xyz="0.0294 0 0"/>
    <parent link="coxa_r1"/>
    <child link="femur_r1"/>
    <axis xyz="0 0 -1"/>
    <limit effort="10" lower="-2.5" upper="2.5" velocity="5.0"/>
  </joint>
  <link name="femur_r1">
    <inertial>
       <origin rpy="0 0 0" xyz="0.04 0 0"/>
       <mass value="0.25"/>
       <inertia ixx="0.0001" ixy="0" ixz="0" iyy="0.0001" iyz="0" izz="0.0001"/>
    </inertial>
    <visual>
      <origin rpy="0 0 0" xyz="0 0 0"/>
      <geometry>
        <mesh filename="meshes/femur_r.STL"/>
      </geometry>
      <material name="cyan">
        <color rgba="0 0.7 0.7 1"/>
      </material>
    </visual>
    <collision>
       <origin rpy="0 1.5708 0" xyz="0.04 0 0"/>
       <geometry>
         <cylinder length="0.08" radius="0.02"/>
       </geometry>
    </collision>
  </link>

  <joint name="tibia_joint_r1" type="revolute">
    <origin rpy="3.14159265359 0 1.57079632679" xyz="0.08 0 0"/>
    <parent link="femur_r1"/>
    <child link="tibia_r1"/>
    <axis xyz="0 0 1"/>
    <limit effort="10" lower="-2.5" upper="2.5" velocity="5.0"/>
  </joint>
  <link name="tibia_r1">
    <inertial>
       <origin rpy="0 0 0" xyz="0.06 0 0"/>
       <mass value="0.25"/>
       <inertia ixx="0.0001" ixy="0" ixz="0" iyy="0.0001" iyz="0" izz="0.0001"/>
    </inertial>
    <visual>
      <origin rpy="0 0 0.06" xyz="0 0 0"/>
      <geometry>
        <mesh filename="meshes/tibia_r.STL"/>
      </geometry>
      <material name="purple">
        <color rgba="0.7 0 0.7 1"/>
      </material>
    </visual>
    <collision>
       <origin rpy="0.2 0 0" xyz="0.06 0 -0.02"/>
       <geometry>
         <cylinder length="0.12" radius="0.015"/>
       </geometry>
    </collision>
  </link>

  <joint name="tibia_foot_joint_r1" type="fixed">
    <origin rpy="0 0 0" xyz="0.117 0 0"/>
    <parent link="tibia_r1"/>
    <child link="tibia_foot_r1"/>
  </joint>
  <link name="tibia_foot_r1">
     <collision>
        <origin rpy="0 0 0" xyz="0 0 0"/>
        <geometry>
           <sphere radius="0.02"/>
        </geometry>
     </collision>
  </link>

  <!-- ======================================================================== -->
  <!-- Leg R2 -->
  <joint name="leg_center_joint_r2" type="fixed">
    <origin rpy="0 0 0" xyz="0 -0.06985 0"/>
    <parent link="thorax"/>
    <child link="leg_center_r2"/>
  </joint>
  <link name="leg_center_r2"/>
  
  <joint name="coxa_joint_r2" type="revolute">
    <origin rpy="0 0 -1.57079632679" xyz="0 0 0"/>
    <parent link="leg_center_r2"/>
    <child link="coxa_r2"/>
    <axis xyz="0 0 -1"/>
    <limit effort="10" lower="-1.5" upper="1.5" velocity="5.0"/>
  </joint>
  <link name="coxa_r2">
    <inertial>
      <origin rpy="0 0 0" xyz="0.02 0 0"/>
      <mass value="0.25"/>
      <inertia ixx="0.0001" ixy="0" ixz="0" iyy="0.0001" iyz="0" izz="0.0001"/>
    </inertial>
    <visual>
      <origin rpy="0 0 0" xyz="0 0 0"/>
      <geometry>
        <mesh filename="meshes/coxa_r.STL"/>
      </geometry>
      <material name="yellow"/>
    </visual>
    <collision>
       <origin rpy="0 1.5708 0" xyz="0.025 0 0"/>
       <geometry>
         <cylinder length="0.05" radius="0.02"/>
       </geometry>
    </collision>
  </link>

  <joint name="femur_joint_r2" type="revolute">
    <origin rpy="-1.57079632679 0 0" xyz="0.0294 0 0"/>
    <parent link="coxa_r2"/>
    <child link="femur_r2"/>
    <axis xyz="0 0 -1"/>
    <limit effort="10" lower="-2.5" upper="2.5" velocity="5.0"/>
  </joint>
  <link name="femur_r2">
    <inertial>
       <origin rpy="0 0 0" xyz="0.04 0 0"/>
       <mass value="0.25"/>
       <inertia ixx="0.0001" ixy="0" ixz="0" iyy="0.0001" iyz="0" izz="0.0001"/>
    </inertial>
    <visual>
      <origin rpy="0 0 0" xyz="0 0 0"/>
      <geometry>
        <mesh filename="meshes/femur_r.STL"/>
      </geometry>
      <material name="cyan"/>
    </visual>
    <collision>
       <origin rpy="0 1.5708 0" xyz="0.04 0 0"/>
       <geometry>
         <cylinder length="0.08" radius="0.02"/>
       </geometry>
    </collision>
  </link>

  <joint name="tibia_joint_r2" type="revolute">
    <origin rpy="3.14159265359 0 1.57079632679" xyz="0.08 0 0"/>
    <parent link="femur_r2"/>
    <child link="tibia_r2"/>
    <axis xyz="0 0 1"/>
    <limit effort="10" lower="-2.5" upper="2.5" velocity="5.0"/>
  </joint>
  <link name="tibia_r2">
    <inertial>
       <origin rpy="0 0 0" xyz="0.06 0 0"/>
       <mass value="0.25"/>
       <inertia ixx="0.0001" ixy="0" ixz="0" iyy="0.0001" iyz="0" izz="0.0001"/>
    </inertial>
    <visual>
      <origin rpy="0 0 0.06" xyz="0 0 0"/>
      <geometry>
        <mesh filename="meshes/tibia_r.STL"/>
      </geometry>
      <material name="purple"/>
    </visual>
    <collision>
       <origin rpy="0.2 0 0" xyz="0.06 0 -0.02"/>
       <geometry>
         <cylinder length="0.12" radius="0.015"/>
       </geometry>
    </collision>
  </link>

  <joint name="tibia_foot_joint_r2" type="fixed">
    <origin rpy="0 0 0" xyz="0.117 0 0"/>
    <parent link="tibia_r2"/>
    <child link="tibia_foot_r2"/>
  </joint>
  <link name="tibia_foot_r2">
     <collision>
        <origin rpy="0 0 0" xyz="0 0 0"/>
        <geometry>
           <sphere radius="0.02"/>
        </geometry>
     </collision>
  </link>

  <!-- ======================================================================== -->
  <!-- Leg R3 -->
  <joint name="leg_center_joint_r3" type="fixed">
    <origin rpy="0 0 0" xyz="-0.087598 -0.050575 0"/>
    <parent link="thorax"/>
    <child link="leg_center_r3"/>
  </joint>
  <link name="leg_center_r3"/>

  <joint name="coxa_joint_r3" type="revolute">
    <origin rpy="0 0 -2.09439510239" xyz="0 0 0"/>
    <parent link="leg_center_r3"/>
    <child link="coxa_r3"/>
    <axis xyz="0 0 -1"/>
    <limit effort="10" lower="-1.5" upper="1.5" velocity="5.0"/>
  </joint>
  <link name="coxa_r3">
    <inertial>
      <origin rpy="0 0 0" xyz="0.02 0 0"/>
      <mass value="0.25"/>
      <inertia ixx="0.0001" ixy="0" ixz="0" iyy="0.0001" iyz="0" izz="0.0001"/>
    </inertial>
    <visual>
      <origin rpy="0 0 0" xyz="0 0 0"/>
      <geometry>
        <mesh filename="meshes/coxa_r.STL"/>
      </geometry>
      <material name="yellow"/>
    </visual>
    <collision>
       <origin rpy="0 1.5708 0" xyz="0.025 0 0"/>
       <geometry>
         <cylinder length="0.05" radius="0.02"/>
       </geometry>
    </collision>
  </link>

  <joint name="femur_joint_r3" type="revolute">
    <origin rpy="-1.57079632679 0 0" xyz="0.0294 0 0"/>
    <parent link="coxa_r3"/>
    <child link="femur_r3"/>
    <axis xyz="0 0 -1"/>
    <limit effort="10" lower="-2.5" upper="2.5" velocity="5.0"/>
  </joint>
  <link name="femur_r3">
    <inertial>
       <origin rpy="0 0 0" xyz="0.04 0 0"/>
       <mass value="0.25"/>
       <inertia ixx="0.0001" ixy="0" ixz="0" iyy="0.0001" iyz="0" izz="0.0001"/>
    </inertial>
    <visual>
      <origin rpy="0 0 0" xyz="0 0 0"/>
      <geometry>
        <mesh filename="meshes/femur_r.STL"/>
      </geometry>
      <material name="cyan"/>
    </visual>
    <collision>
       <origin rpy="0 1.5708 0" xyz="0.04 0 0"/>
       <geometry>
         <cylinder length="0.08" radius="0.02"/>
       </geometry>
    </collision>
  </link>

  <joint name="tibia_joint_r3" type="revolute">
    <origin rpy="3.14159265359 0 1.57079632679" xyz="0.08 0 0"/>
    <parent link="femur_r3"/>
    <child link="tibia_r3"/>
    <axis xyz="0 0 1"/>
    <limit effort="10" lower="-2.5" upper="2.5" velocity="5.0"/>
  </joint>
  <link name="tibia_r3">
    <inertial>
       <origin rpy="0 0 0" xyz="0.06 0 0"/>
       <mass value="0.25"/>
       <inertia ixx="0.0001" ixy="0" ixz="0" iyy="0.0001" iyz="0" izz="0.0001"/>
    </inertial>
    <visual>
      <origin rpy="0 0 0.06" xyz="0 0 0"/>
      <geometry>
        <mesh filename="meshes/tibia_r.STL"/>
      </geometry>
      <material name="purple"/>
    </visual>
    <collision>
       <origin rpy="0.2 0 0" xyz="0.06 0 -0.02"/>
       <geometry>
         <cylinder length="0.12" radius="0.015"/>
       </geometry>
    </collision>
  </link>

  <joint name="tibia_foot_joint_r3" type="fixed">
    <origin rpy="0 0 0" xyz="0.117 0 0"/>
    <parent link="tibia_r3"/>
    <child link="tibia_foot_r3"/>
  </joint>
  <link name="tibia_foot_r3">
     <collision>
        <origin rpy="0 0 0" xyz="0 0 0"/>
        <geometry>
           <sphere radius="0.02"/>
        </geometry>
     </collision>
  </link>

  <!-- ======================================================================== -->
  <!-- Leg L1 -->
  <joint name="leg_center_joint_l1" type="fixed">
    <origin rpy="0 0 0" xyz="0.087598 0.050575 0"/>
    <parent link="thorax"/>
    <child link="leg_center_l1"/>
  </joint>
  <link name="leg_center_l1"/>

  <joint name="coxa_joint_l1" type="revolute">
    <origin rpy="0 0 1.0471975512" xyz="0 0 0"/>
    <parent link="leg_center_l1"/>
    <child link="coxa_l1"/>
    <axis xyz="0 0 -1"/>
    <limit effort="10" lower="-1.5" upper="1.5" velocity="5.0"/>
  </joint>
  <link name="coxa_l1">
    <inertial>
      <origin rpy="0 0 0" xyz="0.02 0 0"/>
      <mass value="0.25"/>
      <inertia ixx="0.0001" ixy="0" ixz="0" iyy="0.0001" iyz="0" izz="0.0001"/>
    </inertial>
    <visual>
      <origin rpy="0 0 0" xyz="0 0 0"/>
      <geometry>
        <mesh filename="meshes/coxa_l.STL"/>
      </geometry>
      <material name="yellow"/>
    </visual>
    <collision>
       <origin rpy="0 1.5708 0" xyz="0.025 0 0"/>
       <geometry>
         <cylinder length="0.05" radius="0.02"/>
       </geometry>
    </collision>
  </link>

  <joint name="femur_joint_l1" type="revolute">
    <origin rpy="-1.57079632679 0 0" xyz="0.0294 0 0"/>
    <parent link="coxa_l1"/>
    <child link="femur_l1"/>
    <axis xyz="0 0 -1"/>
    <limit effort="10" lower="-2.5" upper="2.5" velocity="5.0"/>
  </joint>
  <link name="femur_l1">
    <inertial>
       <origin rpy="0 0 0" xyz="0.04 0 0"/>
       <mass value="0.25"/>
       <inertia ixx="0.0001" ixy="0" ixz="0" iyy="0.0001" iyz="0" izz="0.0001"/>
    </inertial>
    <visual>
      <origin rpy="0 0 0" xyz="0 0 0"/>
      <geometry>
        <mesh filename="meshes/femur_l.STL"/>
      </geometry>
      <material name="cyan"/>
    </visual>
    <collision>
       <origin rpy="0 1.5708 0" xyz="0.04 0 0"/>
       <geometry>
         <cylinder length="0.08" radius="0.02"/>
       </geometry>
    </collision>
  </link>

  <joint name="tibia_joint_l1" type="revolute">
    <origin rpy="3.14159265359 0 1.57079632679" xyz="0.08 0 0"/>
    <parent link="femur_l1"/>
    <child link="tibia_l1"/>
    <axis xyz="0 0 1"/>
    <limit effort="10" lower="-2.5" upper="2.5" velocity="5.0"/>
  </joint>
  <link name="tibia_l1">
    <inertial>
       <origin rpy="0 0 0" xyz="0.06 0 0"/>
       <mass value="0.25"/>
       <inertia ixx="0.0001" ixy="0" ixz="0" iyy="0.0001" iyz="0" izz="0.0001"/>
    </inertial>
    <visual>
      <origin rpy="0 0 0.06" xyz="0 0 0"/>
      <geometry>
        <mesh filename="meshes/tibia_l.STL"/>
      </geometry>
      <material name="purple"/>
    </visual>
    <collision>
       <origin rpy="0.2 0 0" xyz="0.06 0 -0.02"/>
       <geometry>
         <cylinder length="0.12" radius="0.015"/>
       </geometry>
    </collision>
  </link>

  <joint name="tibia_foot_joint_l1" type="fixed">
    <origin rpy="0 0 0" xyz="0.117 0 0"/>
    <parent link="tibia_l1"/>
    <child link="tibia_foot_l1"/>
  </joint>
  <link name="tibia_foot_l1">
     <collision>
        <origin rpy="0 0 0" xyz="0 0 0"/>
        <geometry>
           <sphere radius="0.02"/>
        </geometry>
     </collision>
  </link>

  <!-- ======================================================================== -->
  <!-- Leg L2 -->
  <joint name="leg_center_joint_l2" type="fixed">
    <origin rpy="0 0 0" xyz="0 0.06985 0"/>
    <parent link="thorax"/>
    <child link="leg_center_l2"/>
  </joint>
  <link name="leg_center_l2"/>

  <joint name="coxa_joint_l2" type="revolute">
    <origin rpy="0 0 1.57079632679" xyz="0 0 0"/>
    <parent link="leg_center_l2"/>
    <child link="coxa_l2"/>
    <axis xyz="0 0 -1"/>
    <limit effort="10" lower="-1.5" upper="1.5" velocity="5.0"/>
  </joint>
  <link name="coxa_l2">
    <inertial>
      <origin rpy="0 0 0" xyz="0.02 0 0"/>
      <mass value="0.25"/>
      <inertia ixx="0.0001" ixy="0" ixz="0" iyy="0.0001" iyz="0" izz="0.0001"/>
    </inertial>
    <visual>
      <origin rpy="0 0 0" xyz="0 0 0"/>
      <geometry>
        <mesh filename="meshes/coxa_l.STL"/>
      </geometry>
      <material name="yellow"/>
    </visual>
    <collision>
       <origin rpy="0 1.5708 0" xyz="0.025 0 0"/>
       <geometry>
         <cylinder length="0.05" radius="0.02"/>
       </geometry>
    </collision>
  </link>

  <joint name="femur_joint_l2" type="revolute">
    <origin rpy="-1.57079632679 0 0" xyz="0.0294 0 0"/>
    <parent link="coxa_l2"/>
    <child link="femur_l2"/>
    <axis xyz="0 0 -1"/>
    <limit effort="10" lower="-2.5" upper="2.5" velocity="5.0"/>
  </joint>
  <link name="femur_l2">
    <inertial>
       <origin rpy="0 0 0" xyz="0.04 0 0"/>
       <mass value="0.25"/>
       <inertia ixx="0.0001" ixy="0" ixz="0" iyy="0.0001" iyz="0" izz="0.0001"/>
    </inertial>
    <visual>
      <origin rpy="0 0 0" xyz="0 0 0"/>
      <geometry>
        <mesh filename="meshes/femur_l.STL"/>
      </geometry>
      <material name="cyan"/>
    </visual>
    <collision>
       <origin rpy="0 1.5708 0" xyz="0.04 0 0"/>
       <geometry>
         <cylinder length="0.08" radius="0.02"/>
       </geometry>
    </collision>
  </link>

  <joint name="tibia_joint_l2" type="revolute">
    <origin rpy="3.14159265359 0 1.57079632679" xyz="0.08 0 0"/>
    <parent link="femur_l2"/>
    <child link="tibia_l2"/>
    <axis xyz="0 0 1"/>
    <limit effort="10" lower="-2.5" upper="2.5" velocity="5.0"/>
  </joint>
  <link name="tibia_l2">
    <inertial>
       <origin rpy="0 0 0" xyz="0.06 0 0"/>
       <mass value="0.25"/>
       <inertia ixx="0.0001" ixy="0" ixz="0" iyy="0.0001" iyz="0" izz="0.0001"/>
    </inertial>
    <visual>
      <origin rpy="0 0 0.06" xyz="0 0 0"/>
      <geometry>
        <mesh filename="meshes/tibia_l.STL"/>
      </geometry>
      <material name="purple"/>
    </visual>
    <collision>
       <origin rpy="0.2 0 0" xyz="0.06 0 -0.02"/>
       <geometry>
         <cylinder length="0.12" radius="0.015"/>
       </geometry>
    </collision>
  </link>

  <joint name="tibia_foot_joint_l2" type="fixed">
    <origin rpy="0 0 0" xyz="0.117 0 0"/>
    <parent link="tibia_l2"/>
    <child link="tibia_foot_l2"/>
  </joint>
  <link name="tibia_foot_l2">
     <collision>
        <origin rpy="0 0 0" xyz="0 0 0"/>
        <geometry>
           <sphere radius="0.02"/>
        </geometry>
     </collision>
  </link>

  <!-- ======================================================================== -->
  <!-- Leg L3 -->
  <joint name="leg_center_joint_l3" type="fixed">
    <origin rpy="0 0 0" xyz="-0.087598 0.050575 0"/>
    <parent link="thorax"/>
    <child link="leg_center_l3"/>
  </joint>
  <link name="leg_center_l3"/>

  <joint name="coxa_joint_l3" type="revolute">
    <origin rpy="0 0 2.09439510239" xyz="0 0 0"/>
    <parent link="leg_center_l3"/>
    <child link="coxa_l3"/>
    <axis xyz="0 0 -1"/>
    <limit effort="10" lower="-1.5" upper="1.5" velocity="5.0"/>
  </joint>
  <link name="coxa_l3">
    <inertial>
      <origin rpy="0 0 0" xyz="0.02 0 0"/>
      <mass value="0.25"/>
      <inertia ixx="0.0001" ixy="0" ixz="0" iyy="0.0001" iyz="0" izz="0.0001"/>
    </inertial>
    <visual>
      <origin rpy="0 0 0" xyz="0 0 0"/>
      <geometry>
        <mesh filename="meshes/coxa_l.STL"/>
      </geometry>
      <material name="yellow"/>
    </visual>
    <collision>
       <origin rpy="0 1.5708 0" xyz="0.025 0 0"/>
       <geometry>
         <cylinder length="0.05" radius="0.02"/>
       </geometry>
    </collision>
  </link>

  <joint name="femur_joint_l3" type="revolute">
    <origin rpy="-1.57079632679 0 0" xyz="0.0294 0 0"/>
    <parent link="coxa_l3"/>
    <child link="femur_l3"/>
    <axis xyz="0 0 -1"/>
    <limit effort="10" lower="-2.5" upper="2.5" velocity="5.0"/>
  </joint>
  <link name="femur_l3">
    <inertial>
       <origin rpy="0 0 0" xyz="0.04 0 0"/>
       <mass value="0.25"/>
       <inertia ixx="0.0001" ixy="0" ixz="0" iyy="0.0001" iyz="0" izz="0.0001"/>
    </inertial>
    <visual>
      <origin rpy="0 0 0" xyz="0 0 0"/>
      <geometry>
        <mesh filename="meshes/femur_l.STL"/>
      </geometry>
      <material name="cyan"/>
    </visual>
    <collision>
       <origin rpy="0 1.5708 0" xyz="0.04 0 0"/>
       <geometry>
         <cylinder length="0.08" radius="0.02"/>
       </geometry>
    </collision>
  </link>

  <joint name="tibia_joint_l3" type="revolute">
    <origin rpy="3.14159265359 0 1.57079632679" xyz="0.08 0 0"/>
    <parent link="femur_l3"/>
    <child link="tibia_l3"/>
    <axis xyz="0 0 1"/>
    <limit effort="10" lower="-2.5" upper="2.5" velocity="5.0"/>
  </joint>
  <link name="tibia_l3">
    <inertial>
       <origin rpy="0 0 0" xyz="0.06 0 0"/>
       <mass value="0.25"/>
       <inertia ixx="0.0001" ixy="0" ixz="0" iyy="0.0001" iyz="0" izz="0.0001"/>
    </inertial>
    <visual>
      <origin rpy="0 0 0.06" xyz="0 0 0"/>
      <geometry>
        <mesh filename="meshes/tibia_l.STL"/>
      </geometry>
      <material name="purple"/>
    </visual>
    <collision>
       <origin rpy="0.2 0 0" xyz="0.06 0 -0.02"/>
       <geometry>
         <cylinder length="0.12" radius="0.015"/>
       </geometry>
    </collision>
  </link>

  <joint name="tibia_foot_joint_l3" type="fixed">
    <origin rpy="0 0 0" xyz="0.117 0 0"/>
    <parent link="tibia_l3"/>
    <child link="tibia_foot_l3"/>
  </joint>
  <link name="tibia_foot_l3">
     <collision>
        <origin rpy="0 0 0" xyz="0 0 0"/>
        <geometry>
           <sphere radius="0.02"/>
        </geometry>
     </collision>
  </link>
</robot>
